Traceback (most recent call last):
  File "/usr/lib/python3.11/site-packages/jupyter_cache/executors/utils.py", line 58, in single_nb_execution
    executenb(
  File "/usr/lib/python3.11/site-packages/nbclient/client.py", line 1314, in execute
    return NotebookClient(nb=nb, resources=resources, km=km, **kwargs).execute()
           ^^^^^^^^^^^^^^^^^^^^^^^^^^^^^^^^^^^^^^^^^^^^^^^^^^^^^^^^^^^^^^^^^^^^^
  File "/usr/lib/python3.11/site-packages/jupyter_core/utils/__init__.py", line 165, in wrapped
    return loop.run_until_complete(inner)
           ^^^^^^^^^^^^^^^^^^^^^^^^^^^^^^
  File "/usr/lib/python3.11/asyncio/base_events.py", line 654, in run_until_complete
    return future.result()
           ^^^^^^^^^^^^^^^
  File "/usr/lib/python3.11/site-packages/nbclient/client.py", line 709, in async_execute
    await self.async_execute_cell(
  File "/usr/lib/python3.11/site-packages/nbclient/client.py", line 1062, in async_execute_cell
    await self._check_raise_for_error(cell, cell_index, exec_reply)
  File "/usr/lib/python3.11/site-packages/nbclient/client.py", line 918, in _check_raise_for_error
    raise CellExecutionError.from_cell_and_msg(cell, exec_reply_content)
nbclient.exceptions.CellExecutionError: An error occurred while executing the following cell:
------------------
dracor.add_corpus_from_repo(repository_name="poldracor")
------------------


[0;31m---------------------------------------------------------------------------[0m
[0;31mUnboundLocalError[0m                         Traceback (most recent call last)
Cell [0;32mIn[4], line 1[0m
[0;32m----> 1[0m [43mdracor[49m[38;5;241;43m.[39;49m[43madd_corpus_from_repo[49m[43m([49m[43mrepository_name[49m[38;5;241;43m=[39;49m[38;5;124;43m"[39;49m[38;5;124;43mpoldracor[39;49m[38;5;124;43m"[39;49m[43m)[49m

File [0;32m/usr/lib/python3.11/site-packages/stabledracor/client.py:2395[0m, in [0;36mStableDraCor.add_corpus_from_repo[0;34m(self, commit, repository_name, repository_owner, repository_base_url, repository_data_folder, use_metadata_of_corpus_xml, corpus_metadata, exclude)[0m
[1;32m   2392[0m         logging[38;5;241m.[39mdebug([38;5;124mf[39m[38;5;124m"[39m[38;5;124mRequesting the tree of the root folder was not successful.[39m[38;5;124m"[39m)
[1;32m   2393[0m         corpus_xml_blob_url [38;5;241m=[39m [38;5;28;01mNone[39;00m
[0;32m-> 2395[0m [38;5;28;01mif[39;00m [43mcorpus_xml_blob_url[49m [38;5;129;01mis[39;00m [38;5;129;01mnot[39;00m [38;5;28;01mNone[39;00m:
[1;32m   2396[0m     [38;5;66;03m# TODO: Continue here. Need to change to get_github_api stuff[39;00m
[1;32m   2397[0m     blob_data [38;5;241m=[39m [38;5;28mself[39m[38;5;241m.[39m__github_api_get(url[38;5;241m=[39mcorpus_xml_blob_url)
[1;32m   2398[0m     [38;5;28;01mif[39;00m [38;5;124m"[39m[38;5;124mcontent[39m[38;5;124m"[39m [38;5;129;01min[39;00m blob_data:

[0;31mUnboundLocalError[0m: cannot access local variable 'corpus_xml_blob_url' where it is not associated with a value

